Workbook
Name Slicer_City: #N/A
Name Slicer_Coupon_Code: #N/A
Name Slicer_Gender: #N/A
Name Slicer_Product_Category: #N/A
Name Slicer_PRODUCTS: #N/A
Name Slicer_Referral_Source: #N/A

Sheet Raw Data
A1: OrderID | B1: Date | C1: CustomerID | D1: Product | E1: Quantity | F1: UnitPrice | G1: ShippingAddress | H1: PaymentMethod | I1: OrderStatus | J1: TrackingNumber | K1: ItemsInCart | L1: CouponCode | M1: ReferralSource | N1: TotalPrice
A2: ORD200000 | B2: 44930 | C2: C72649 | D2: Monitor | E2: 5 | F2: 570.62 | G2: 928 Main St | H2: Debit Card | I2: Shipped | J2: TRK37947903 | K2: 7 | L2: SAVE10 | M2: Instagram | N2: 2853.1
A3: ORD200001 | B3: 45527 | C3: C75739 | D3: Phone | E3: 2 | F3: 151.35 | G3: 823 Main St | H3: Online | I3: Shipped | J3: TRK91186779 | K3: 3 | L3: SAVE10 | M3: Referral | N3: 302.7
A4: ORD200002 | B4: 45349 | C4: C81728 | D4: Tablet | E4: 5 | F4: 550.68 | G4: 512 Main St | H4: Credit Card | I4: Cancelled | J4: TRK42903982 | K4: 8 | L4: FREESHIP | M4: Email | N4: 2753.4
A5: ORD200003 | B5: 45214 | C5: C33540 | D5: Chair | E5: 1 | F5: 273.19 | G5: 275 Main St | H5: Debit Card | I5: Returned | J5: TRK62788070 | K5: 5 | L5: SAVE10 | M5: Facebook | N5: 273.19
A6: ORD200004 | B6: 45785 | C6: C81840 | D6: Printer | E6: 4 | F6: 626.01 | G6: 668 Main St | H6: Online | I6: Delivered | J6: TRK29241424 | K6: 8 | L6: SAVE10 | M6: Email | N6: 2504.04
A7: ORD200005 | B7: 45222 | C7: C37249 | D7: Phone | E7: 2 | F7: 245.86 | G7: 934 Main St | H7: Credit Card | I7: Shipped | J7: TRK72976927 | K7: 4 | L7: SAVE10 | M7: Instagram | N7: 491.72
A8: ORD200006 | B8: 45825 | C8: C83492 | D8: Laptop | E8: 1 | F8: 664.42 | G8: 986 Main St | H8: Gift Card | I8: Returned | J8: TRK96417362 | K8: 6 | L8: SAVE10 | M8: Facebook | N8: 664.42
A9: ORD200007 | B9: 45058 | C9: C41460 | D9: Monitor | E9: 5 | F9: 149.55 | G9: 706 Main St | H9: Cash | I9: Shipped | J9: TRK78809193 | K9: 9 | L9: FREESHIP | M9: Facebook | N9: 747.75
A10: ORD200008 | B10: 45749 | C10: C26817 | D10: Phone | E10: 2 | F10: 134.28 | G10: 904 Main St | H10: Gift Card | I10: Cancelled | J10: TRK61042692 | K10: 2 | M10: Email | N10: 268.56
A11: ORD200009 | B11: 45251 | C11: C31946 | D11: Desk | E11: 4 | F11: 509.38 | G11: 102 Main St | H11: Credit Card | I11: Shipped | J11: TRK33478363 | K11: 6 | L11: SAVE10 | M11: Google | N11: 2037.52
A12: ORD200010 | B12: 45289 | C12: C43443 | D12: Tablet | E12: 5 | F12: 625.97 | G12: 333 Main St | H12: Credit Card | I12: Returned | J12: TRK98859248 | K12: 9 | L12: WINTER15 | M12: Instagram | N12: 3129.85
A13: ORD200011 | B13: 45339 | C13: C93861 | D13: Monitor | E13: 3 | F13: 49.14 | G13: 831 Main St | H13: Online | I13: Returned | J13: TRK48234646 | K13: 7 | L13: SAVE10 | M13: Email | N13: 147.42
A14: ORD200012 | B14: 45580 | C14: C38785 | D14: Monitor | E14: 2 | F14: 180.5 | G14: 179 Main St | H14: Debit Card | I14: Pending | J14: TRK20419991 | K14: 6 | L14: FREESHIP | M14: Referral | N14: 361
A15: ORD200013 | B15: 45168 | C15: C88348 | D15: Laptop | E15: 3 | F15: 201.49 | G15: 903 Main St | H15: Credit Card | I15: Returned | J15: TRK81913874 | K15: 4 | L15: FREESHIP | M15: Facebook | N15: 604.47
A16: ORD200014 | B16: 45012 | C16: C98474 | D16: Tablet | E16: 2 | F16: 393.33 | G16: 980 Main St | H16: Debit Card | I16: Pending | J16: TRK79186539 | K16: 3 | L16: SAVE10 | M16: Instagram | N16: 786.66
A17: ORD200015 | B17: 45124 | C17: C39416 | D17: Printer | E17: 1 | F17: 473.96 | G17: 942 Main St | H17: Cash | I17: Delivered | J17: TRK54930938 | K17: 3 | M17: Google | N17: 473.96
A18: ORD200016 | B18: 44950 | C18: C28976 | D18: Printer | E18: 2 | F18: 533.81 | G18: 914 Main St | H18: Credit Card | I18: Pending | J18: TRK13194259 | K18: 3 | L18: FREESHIP | M18: Email | N18: 1067.62
A19: ORD200017 | B19: 45353 | C19: C60672 | D19: Tablet | E19: 1 | F19: 423.4 | G19: 382 Main St | H19: Debit Card | I19: Shipped | J19: TRK11972116 | K19: 3 | M19: Referral | N19: 423.4
A20: ORD200018 | B20: 45742 | C20: C84329 | D20: Desk | E20: 1 | F20: 431.44 | G20: 891 Main St | H20: Gift Card | I20: Pending | J20: TRK65191045 | K20: 3 | L20: SAVE10 | M20: Facebook | N20: 431.44
A21: ORD200019 | B21: 44949 | C21: C14552 | D21: Monitor | E21: 5 | F21: 224 | G21: 273 Main St | H21: Cash | I21: Returned | J21: TRK59101365 | K21: 9 | L21: SAVE10 | M21: Google | N21: 1120
A22: ORD200020 | B22: 45054 | C22: C54829 | D22: Chair | E22: 5 | F22: 62.51 | G22: 587 Main St | H22: Cash | I22: Pending | J22: TRK16718651 | K22: 9 | L22: WINTER15 | M22: Instagram | N22: 312.55
A23: ORD200021 | B23: 45613 | C23: C99023 | D23: Monitor | E23: 4 | F23: 342.95 | G23: 569 Main St | H23: Cash | I23: Delivered | J23: TRK52646983 | K23: 6 | M23: Google | N23: 1371.8
A24: ORD200022 | B24: 44955 | C24: C34416 | D24: Monitor | E24: 2 | F24: 49.62 | G24: 633 Main St | H24: Online | I24: Pending | J24: TRK75937350 | K24: 2 | L24: SAVE10 | M24: Google | N24: 99.24
A25: ORD200023 | B25: 45756 | C25: C42372 | D25: Phone | E25: 4 | F25: 273.25 | G25: 755 Main St | H25: Debit Card | I25: Cancelled | J25: TRK36168083 | K25: 5 | L25: FREESHIP | M25: Referral | N25: 1093
A26: ORD200024 | B26: 45595 | C26: C17470 | D26: Laptop | E26: 2 | F26: 230.95 | G26: 956 Main St | H26: Online | I26: Delivered | J26: TRK28775057 | K26: 3 | L26: WINTER15 | M26: Referral | N26: 461.9
A27: ORD200025 | B27: 45497 | C27: C42577 | D27: Monitor | E27: 1 | F27: 399.98 | G27: 709 Main St | H27: Debit Card | I27: Delivered | J27: TRK69423327 | K27: 3 | L27: WINTER15 | M27: Email | N27: 399.98
A28: ORD200026 | B28: 45357 | C28: C21944 | D28: Laptop | E28: 5 | F28: 59.55 | G28: 296 Main St | H28: Online | I28: Delivered | J28: TRK80276812 | K28: 6 | M28: Referral | N28: 297.75
A29: ORD200027 | B29: 45344 | C29: C97593 | D29: Printer | E29: 1 | F29: 472.74 | G29: 881 Main St | H29: Online | I29: Shipped | J29: TRK89117573 | K29: 6 | L29: WINTER15 | M29: Google | N29: 472.74
A30: ORD200028 | B30: 45251 | C30: C59823 | D30: Phone | E30: 4 | F30: 160.07 | G30: 568 Main St | H30: Online | I30: Pending | J30: TRK65895539 | K30: 5 | M30: Email | N30: 640.28
A31: ORD200029 | B31: 45555 | C31: C33260 | D31: Desk | E31: 3 | F31: 423.53 | G31: 930 Main St | H31: Credit Card | I31: Delivered | J31: TRK59744090 | K31: 6 | L31: SAVE10 | M31: Referral | N31: 1270.59
A32: ORD200030 | B32: 45738 | C32: C44267 | D32: Monitor | E32: 2 | F32: 426.7 | G32: 895 Main St | H32: Online | I32: Pending | J32: TRK54751444 | K32: 5 | L32: SAVE10 | M32: Referral | N32: 853.4
A33: ORD200031 | B33: 45107 | C33: C26445 | D33: Chair | E33: 3 | F33: 500.08 | G33: 996 Main St | H33: Debit Card | I33: Returned | J33: TRK31229981 | K33: 6 | M33: Facebook | N33: 1500.24
A34: ORD200032 | B34: 45047 | C34: C12388 | D34: Tablet | E34: 5 | F34: 536.72 | G34: 830 Main St | H34: Cash | I34: Delivered | J34: TRK99261395 | K34: 10 | M34: Email | N34: 2683.6
A35: ORD200033 | B35: 45082 | C35: C52184 | D35: Chair | E35: 1 | F35: 162.77 | G35: 912 Main St | H35: Online | I35: Cancelled | J35: TRK73312471 | K35: 4 | L35: WINTER15 | M35: Facebook | N35: 162.77
A36: ORD200034 | B36: 44933 | C36: C67195 | D36: Chair | E36: 4 | F36: 576.52 | G36: 926 Main St | H36: Credit Card | I36: Pending | J36: TRK55467915 | K36: 5 | L36: WINTER15 | M36: Facebook | N36: 2306.08
A37: ORD200035 | B37: 45633 | C37: C50304 | D37: Monitor | E37: 2 | F37: 465.15 | G37: 128 Main St | H37: Online | I37: Shipped | J37: TRK46850888 | K37: 2 | L37: SAVE10 | M37: Facebook | N37: 930.3
A38: ORD200036 | B38: 45785 | C38: C59337 | D38: Laptop | E38: 2 | F38: 534.43 | G38: 465 Main St | H38: Debit Card | I38: Pending | J38: TRK50961250 | K38: 5 | M38: Facebook | N38: 1068.86
A39: ORD200037 | B39: 45579 | C39: C10054 | D39: Laptop | E39: 2 | F39: 76.74 | G39: 409 Main St | H39: Cash | I39: Returned | J39: TRK94005261 | K39: 7 | L39: SAVE10 | M39: Instagram | N39: 153.48
A40: ORD200038 | B40: 45645 | C40: C15924 | D40: Laptop | E40: 1 | F40: 245.89 | G40: 549 Main St | H40: Debit Card | I40: Delivered | J40: TRK14835975 | K40: 3 | L40: SAVE10 | M40: Google | N40: 245.89
...

Sheet Customer Data
A1: Customer_ID | B1: Customer Name | C1: Gender | D1: Age | E1: City
A2: C72649 | B2: ="Customer_" & ROW() -> Customer_2 | C2: Male | D2: 40 | E2: Lagos
A3: C75739 | B3: ="Customer_" & ROW() -> Customer_3 | C3: Female | D3: 44 | E3: Abuja
A4: C81728 | B4: ="Customer_" & ROW() -> Customer_4 | C4: Female | D4: 25 | E4: Abuja
A5: C33540 | B5: ="Customer_" & ROW() -> Customer_5 | C5: Female | D5: 46 | E5: Enugu
A6: C81840 | B6: ="Customer_" & ROW() -> Customer_6 | C6: Male | D6: 55 | E6: Abuja
A7: C37249 | B7: ="Customer_" & ROW() -> Customer_7 | C7: Female | D7: 18 | E7: Port-Harcourt
A8: C83492 | B8: ="Customer_" & ROW() -> Customer_8 | C8: Female | D8: 33 | E8: Kano
A9: C41460 | B9: ="Customer_" & ROW() -> Customer_9 | C9: Female | D9: 59 | E9: Owerri
A10: C26817 | B10: ="Customer_" & ROW() -> Customer_10 | C10: Male | D10: 41 | E10: Port-Harcourt
A11: C31946 | B11: ="Customer_" & ROW() -> Customer_11 | C11: Female | D11: 56 | E11: Kano
A12: C43443 | B12: ="Customer_" & ROW() -> Customer_12 | C12: Female | D12: 21 | E12: Kano
A13: C93861 | B13: ="Customer_" & ROW() -> Customer_13 | C13: Female | D13: 19 | E13: Lagos
... A1201: C57502 | B1201: ="Customer_" & ROW() -> Customer_1201 | C1201: Male | D1201: 36 | E1201: Kano

Sheet Product Category
A1: Product | B1: Category
A2: Chair | B2: Furniture
A3: Desk | B3: Furniture
A4: Laptop | B4: Electronics
A5: Monitor | B5: Electronics
A6: Phone | B6: Electronics
A7: Printer | B7: Electronics
A8: Tablet | B8: Electronics

Sheet Coupons
A1: Coupon Code | B1: Discount
A2: WINTER15 | B2: 0.15
A3: SAVE10 | B3: 0.1
A4: FREESHIP | B4: 0
A5: NO COUPON | B5: 0

Sheet Clean Data
A1: OrderID | B1: Order_ID | C1: Date | D1: Order Date | E1: Order Year | F1: Order Month | G1: Order Day | H1: CustomerID | I1: Customer_ID | J1: Product | K1: PRODUCTS | L1: Quantity | M1: UnitPrice | N1: Unit_Price | O1: ShippingAddress | P1: Street Number | Q1: Street Name | R1: PaymentMethod | S1: Payment_Method | T1: OrderStatus | U1: Order_Status | V1: TrackingNumber | W1: Tracking_Number | X1: Items In Cart | Y1: CouponCode | Z1: Coupon_Code | AA1: Coupon Usage | AB1: ReferralSource | AC1: Referral_Source | AD1: TotalPrice | AE1: Total_Price | AF1: Revenue | AG1: Customer Name | AH1: Gender | AI1: Age | AJ1: City | AK1: Product Category | AL1: Discount | AM1: Discount Amount | AN1: Cost Per Unit | AO1: Total Cost Price | AP1: Net Revenue | AQ1: Profit | AR1: Profit Margin | AS1: KPI Summary
A2: ORD200000 | B2: =(RIGHT(A2, LEN(A2)-3))*1 -> 200000 | C2: 44930 | D2: 44930 | E2: =(TEXT(D2, "yyyy"))*1 -> 2023 | F2: =TEXT(D2, "mmmm") -> January | G2: =TEXT(D2, "dddd") -> Wednesday | H2: C72649 | I2: =(RIGHT(H2, LEN(H2)-1))*1 -> 72649 | J2: Monitor | K2: =TRIM(PROPER(J2)) -> Monitor | L2: 5 | M2: 570.62 | N2: =(TRIM(PROPER(M2)))*1 -> 570.62 | O2: 928 Main St | P2: =LEFT(O2, FIND(" ", O2)-1) -> 928 | Q2: =RIGHT(O2, LEN(O2) - FIND(" ", O2)) -> Main St | R2: Debit Card | S2: =TRIM(PROPER(R2)) -> Debit Card | T2: Shipped | U2: =TRIM(PROPER(T2)) -> Shipped | V2: TRK37947903 | W2: =RIGHT(V2, LEN(V2)-3) -> 37947903 | X2: 7 | Y2: SAVE10 | Z2: =TRIM(UPPER(IF(Y2="", "NO COUPON", Y2))) -> SAVE10 | AA2: =IF(Z2="NO COUPON","NO","YES") -> YES | AB2: Instagram | AC2: =TRIM(PROPER(AB2)) -> Instagram | AD2: 2853.1 | AE2: 2853.1 | AF2: =N2*L2 -> 2853.1 | AG2: =_xlfn.XLOOKUP(H2, 'Customer Data'!A2,'Customer Data'!B2) -> Customer_2 | AH2: =_xlfn.XLOOKUP(H2,'Customer Data'!A2,'Customer Data'!C2) -> Male | AI2: =_xlfn.XLOOKUP(H2,'Customer Data'!A2,'Customer Data'!D2) -> 40 | AJ2: =_xlfn.XLOOKUP(H2,'Customer Data'!A2,'Customer Data'!E2) -> Lagos | AK2: =VLOOKUP(K2,'Product Category'!A:B,2,FALSE) -> Electronics | AL2: =VLOOKUP(Z2,Coupons!A:B,2,FALSE) -> 0.1 | AM2: =AE2*AL2 -> 285.31 | AN2: =N2*0.7 -> 399.434 | AO2: =AN2*L2 -> 1997.17 | AP2: =AF2-AM2 -> 2567.79 | AQ2: =AP2-AO2 -> 570.62 | AR2: =AP2/AO2 -> 1.2857143 | AS2: TOTAL NET REVENUE | AT2: =SUM(AP2:AP1201) -> 1188905.4
A3: ORD200001 | B3: =(RIGHT(A3, LEN(A3)-3))*1 -> 200001 | C3: 45527 | D3: 45527 | E3: =(TEXT(D3, "yyyy"))*1 -> 2024 | F3: =TEXT(D3, "mmmm") -> August | G3: =TEXT(D3, "dddd") -> Friday | H3: C75739 | I3: =(RIGHT(H3, LEN(H3)-1))*1 -> 75739 | J3: Phone | K3: =TRIM(PROPER(J3)) -> Phone | L3: 2 | M3: 151.35 | N3: =(TRIM(PROPER(M3)))*1 -> 151.35 | O3: 823 Main St | P3: =LEFT(O3, FIND(" ", O3)-1) -> 823 | Q3: =RIGHT(O3, LEN(O3) - FIND(" ", O3)) -> Main St | R3: Online | S3: =TRIM(PROPER(R3)) -> Online | T3: Shipped | U3: =TRIM(PROPER(T3)) -> Shipped | V3: TRK91186779 | W3: =RIGHT(V3, LEN(V3)-3) -> 91186779 | X3: 3 | Y3: SAVE10 | Z3: =TRIM(UPPER(IF(Y3="", "NO COUPON", Y3))) -> SAVE10 | AA3: =IF(Z3="NO COUPON","NO","YES") -> YES | AB3: Referral | AC3: =TRIM(PROPER(AB3)) -> Referral | AD3: 302.7 | AE3: 302.7 | AF3: =N3*L3 -> 302.7 | AG3: =_xlfn.XLOOKUP(H3, 'Customer Data'!A3,'Customer Data'!B3) -> Customer_3 | AH3: =_xlfn.XLOOKUP(H3,'Customer Data'!A3,'Customer Data'!C3) -> Female | AI3: =_xlfn.XLOOKUP(H3,'Customer Data'!A3,'Customer Data'!D3) -> 44 | AJ3: =_xlfn.XLOOKUP(H3,'Customer Data'!A3,'Customer Data'!E3) -> Abuja | AK3: =VLOOKUP(K3,'Product Category'!A:B,2,FALSE) -> Electronics | AL3: =VLOOKUP(Z3,Coupons!A:B,2,FALSE) -> 0.1 | AM3: =AE3*AL3 -> 30.27 | AN3: =N3*0.7 -> 105.945 | AO3: =AN3*L3 -> 211.89 | AP3: =AF3-AM3 -> 272.43 | AQ3: =AP3-AO3 -> 60.54 | AR3: =AP3/AO3 -> 1.2857143 | AS3: TOTAL ORDERS | AT3: =COUNT(B2:B1201) -> 1200
A4: ORD200002 | B4: =(RIGHT(A4, LEN(A4)-3))*1 -> 200002 | C4: 45349 | D4: 45349 | E4: =(TEXT(D4, "yyyy"))*1 -> 2024 | F4: =TEXT(D4, "mmmm") -> February | G4: =TEXT(D4, "dddd") -> Tuesday | H4: C81728 | I4: =(RIGHT(H4, LEN(H4)-1))*1 -> 81728 | J4: Tablet | K4: =TRIM(PROPER(J4)) -> Tablet | L4: 5 | M4: 550.68 | N4: =(TRIM(PROPER(M4)))*1 -> 550.68 | O4: 512 Main St | P4: =LEFT(O4, FIND(" ", O4)-1) -> 512 | Q4: =RIGHT(O4, LEN(O4) - FIND(" ", O4)) -> Main St | R4: Credit Card | S4: =TRIM(PROPER(R4)) -> Credit Card | T4: Cancelled | U4: =TRIM(PROPER(T4)) -> Cancelled | V4: TRK42903982 | W4: =RIGHT(V4, LEN(V4)-3) -> 42903982 | X4: 8 | Y4: FREESHIP | Z4: =TRIM(UPPER(IF(Y4="", "NO COUPON", Y4))) -> FREESHIP | AA4: =IF(Z4="NO COUPON","NO","YES") -> YES | AB4: Email | AC4: =TRIM(PROPER(AB4)) -> Email | AD4: 2753.4 | AE4: 2753.4 | AF4: =N4*L4 -> 2753.4 | AG4: =_xlfn.XLOOKUP(H4, 'Customer Data'!A4,'Customer Data'!B4) -> Customer_4 | AH4: =_xlfn.XLOOKUP(H4,'Customer Data'!A4,'Customer Data'!C4) -> Female | AI4: =_xlfn.XLOOKUP(H4,'Customer Data'!A4,'Customer Data'!D4) -> 25 | AJ4: =_xlfn.XLOOKUP(H4,'Customer Data'!A4,'Customer Data'!E4) -> Abuja | AK4: =VLOOKUP(K4,'Product Category'!A:B,2,FALSE) -> Electronics | AL4: =VLOOKUP(Z4,Coupons!A:B,2,FALSE) -> 0 | AM4: =AE4*AL4 -> 0 | AN4: =N4*0.7 -> 385.476 | AO4: =AN4*L4 -> 1927.38 | AP4: =AF4-AM4 -> 2753.4 | AQ4: =AP4-AO4 -> 826.02 | AR4: =AP4/AO4 -> 1.4285714 | AS4: AVERAGE ORDER VALUE | AT4: =AVERAGE(AP2:AP1201) -> 990.75452
A5: ORD200003 | B5: =(RIGHT(A5, LEN(A5)-3))*1 -> 200003 | C5: 45214 | D5: 45214 | E5: =(TEXT(D5, "yyyy"))*1 -> 2023 | F5: =TEXT(D5, "mmmm") -> October | G5: =TEXT(D5, "dddd") -> Sunday | H5: C33540 | I5: =(RIGHT(H5, LEN(H5)-1))*1 -> 33540 | J5: Chair | K5: =TRIM(PROPER(J5)) -> Chair | L5: 1 | M5: 273.19 | N5: =(TRIM(PROPER(M5)))*1 -> 273.19 | O5: 275 Main St | P5: =LEFT(O5, FIND(" ", O5)-1) -> 275 | Q5: =RIGHT(O5, LEN(O5) - FIND(" ", O5)) -> Main St | R5: Debit Card | S5: =TRIM(PROPER(R5)) -> Debit Card | T5: Returned | U5: =TRIM(PROPER(T5)) -> Returned | V5: TRK62788070 | W5: =RIGHT(V5, LEN(V5)-3) -> 62788070 | X5: 5 | Y5: SAVE10 | Z5: =TRIM(UPPER(IF(Y5="", "NO COUPON", Y5))) -> SAVE10 | AA5: =IF(Z5="NO COUPON","NO","YES") -> YES | AB5: Facebook | AC5: =TRIM(PROPER(AB5)) -> Facebook | AD5: 273.19 | AE5: 273.19 | AF5: =N5*L5 -> 273.19 | AG5: =_xlfn.XLOOKUP(H5, 'Customer Data'!A5,'Customer Data'!B5) -> Customer_5 | AH5: =_xlfn.XLOOKUP(H5,'Customer Data'!A5,'Customer Data'!C5) -> Female | AI5: =_xlfn.XLOOKUP(H5,'Customer Data'!A5,'Customer Data'!D5) -> 46 | AJ5: =_xlfn.XLOOKUP(H5,'Customer Data'!A5,'Customer Data'!E5) -> Enugu | AK5: =VLOOKUP(K5,'Product Category'!A:B,2,FALSE) -> Furniture | AL5: =VLOOKUP(Z5,Coupons!A:B,2,FALSE) -> 0.1 | AM5: =AE5*AL5 -> 27.319 | AN5: =N5*0.7 -> 191.233 | AO5: =AN5*L5 -> 191.233 | AP5: =AF5-AM5 -> 245.871 | AQ5: =AP5-AO5 -> 54.638 | AR5: =AP5/AO5 -> 1.2857143 | AS5: TOTAL PROFIT | AT5: =SUM(AQ2:AQ1201) -> 303572.05
A6: ORD200004 | B6: =(RIGHT(A6, LEN(A6)-3))*1 -> 200004 | C6: 45785 | D6: 45785 | E6: =(TEXT(D6, "yyyy"))*1 -> 2025 | F6: =TEXT(D6, "mmmm") -> May | G6: =TEXT(D6, "dddd") -> Thursday | H6: C81840 | I6: =(RIGHT(H6, LEN(H6)-1))*1 -> 81840 | J6: Printer | K6: =TRIM(PROPER(J6)) -> Printer | L6: 4 | M6: 626.01 | N6: =(TRIM(PROPER(M6)))*1 -> 626.01 | O6: 668 Main St | P6: =LEFT(O6, FIND(" ", O6)-1) -> 668 | Q6: =RIGHT(O6, LEN(O6) - FIND(" ", O6)) -> Main St | R6: Online | S6: =TRIM(PROPER(R6)) -> Online | T6: Delivered | U6: =TRIM(PROPER(T6)) -> Delivered | V6: TRK29241424 | W6: =RIGHT(V6, LEN(V6)-3) -> 29241424 | X6: 8 | Y6: SAVE10 | Z6: =TRIM(UPPER(IF(Y6="", "NO COUPON", Y6))) -> SAVE10 | AA6: =IF(Z6="NO COUPON","NO","YES") -> YES | AB6: Email | AC6: =TRIM(PROPER(AB6)) -> Email | AD6: 2504.04 | AE6: 2504.04 | AF6: =N6*L6 -> 2504.04 | AG6: =_xlfn.XLOOKUP(H6, 'Customer Data'!A6,'Customer Data'!B6) -> Customer_6 | AH6: =_xlfn.XLOOKUP(H6,'Customer Data'!A6,'Customer Data'!C6) -> Male | AI6: =_xlfn.XLOOKUP(H6,'Customer Data'!A6,'Customer Data'!D6) -> 55 | AJ6: =_xlfn.XLOOKUP(H6,'Customer Data'!A6,'Customer Data'!E6) -> Abuja | AK6: =VLOOKUP(K6,'Product Category'!A:B,2,FALSE) -> Electronics | AL6: =VLOOKUP(Z6,Coupons!A:B,2,FALSE) -> 0.1 | AM6: =AE6*AL6 -> 250.404 | AN6: =N6*0.7 -> 438.207 | AO6: =AN6*L6 -> 1752.828 | AP6: =AF6-AM6 -> 2253.636 | AQ6: =AP6-AO6 -> 500.808 | AR6: =AP6/AO6 -> 1.2857143 | AS6: TOTAL PROFIT MARGIN | AT6: =AT5/AT2 -> 0.25533743
A7: ORD200005 | B7: =(RIGHT(A7, LEN(A7)-3))*1 -> 200005 | C7: 45222 | D7: 45222 | E7: =(TEXT(D7, "yyyy"))*1 -> 2023 | F7: =TEXT(D7, "mmmm") -> October | G7: =TEXT(D7, "dddd") -> Monday | H7: C37249 | I7: =(RIGHT(H7, LEN(H7)-1))*1 -> 37249 | J7: Phone | K7: =TRIM(PROPER(J7)) -> Phone | L7: 2 | M7: 245.86 | N7: =(TRIM(PROPER(M7)))*1 -> 245.86 | O7: 934 Main St | P7: =LEFT(O7, FIND(" ", O7)-1) -> 934 | Q7: =RIGHT(O7, LEN(O7) - FIND(" ", O7)) -> Main St | R7: Credit Card | S7: =TRIM(PROPER(R7)) -> Credit Card | T7: Shipped | U7: =TRIM(PROPER(T7)) -> Shipped | V7: TRK72976927 | W7: =RIGHT(V7, LEN(V7)-3) -> 72976927 | X7: 4 | Y7: SAVE10 | Z7: =TRIM(UPPER(IF(Y7="", "NO COUPON", Y7))) -> SAVE10 | AA7: =IF(Z7="NO COUPON","NO","YES") -> YES | AB7: Instagram | AC7: =TRIM(PROPER(AB7)) -> Instagram | AD7: 491.72 | AE7: 491.72 | AF7: =N7*L7 -> 491.72 | AG7: =_xlfn.XLOOKUP(H7, 'Customer Data'!A7,'Customer Data'!B7) -> Customer_7 | AH7: =_xlfn.XLOOKUP(H7,'Customer Data'!A7,'Customer Data'!C7) -> Female | AI7: =_xlfn.XLOOKUP(H7,'Customer Data'!A7,'Customer Data'!D7) -> 18 | AJ7: =_xlfn.XLOOKUP(H7,'Customer Data'!A7,'Customer Data'!E7) -> Port-Harcourt | AK7: =VLOOKUP(K7,'Product Category'!A:B,2,FALSE) -> Electronics | AL7: =VLOOKUP(Z7,Coupons!A:B,2,FALSE) -> 0.1 | AM7: =AE7*AL7 -> 49.172 | AN7: =N7*0.7 -> 172.102 | AO7: =AN7*L7 -> 344.204 | AP7: =AF7-AM7 -> 442.548 | AQ7: =AP7-AO7 -> 98.344 | AR7: =AP7/AO7 -> 1.2857143 | AS7: TOTAL CUSTOMERS | AT7: =COUNT(I2:I1201) -> 1200
A8: ORD200006 | B8: =(RIGHT(A8, LEN(A8)-3))*1 -> 200006 | C8: 45825 | D8: 45825 | E8: =(TEXT(D8, "yyyy"))*1 -> 2025 | F8: =TEXT(D8, "mmmm") -> June | G8: =TEXT(D8, "dddd") -> Tuesday | H8: C83492 | I8: =(RIGHT(H8, LEN(H8)-1))*1 -> 83492 | J8: Laptop | K8: =TRIM(PROPER(J8)) -> Laptop | L8: 1 | M8: 664.42 | N8: =(TRIM(PROPER(M8)))*1 -> 664.42 | O8: 986 Main St | P8: =LEFT(O8, FIND(" ", O8)-1) -> 986 | Q8: =RIGHT(O8, LEN(O8) - FIND(" ", O8)) -> Main St | R8: Gift Card | S8: =TRIM(PROPER(R8)) -> Gift Card | T8: Returned | U8: =TRIM(PROPER(T8)) -> Returned | V8: TRK96417362 | W8: =RIGHT(V8, LEN(V8)-3) -> 96417362 | X8: 6 | Y8: SAVE10 | Z8: =TRIM(UPPER(IF(Y8="", "NO COUPON", Y8))) -> SAVE10 | AA8: =IF(Z8="NO COUPON","NO","YES") -> YES | AB8: Facebook | AC8: =TRIM(PROPER(AB8)) -> Facebook | AD8: 664.42 | AE8: 664.42 | AF8: =N8*L8 -> 664.42 | AG8: =_xlfn.XLOOKUP(H8, 'Customer Data'!A8,'Customer Data'!B8) -> Customer_8 | AH8: =_xlfn.XLOOKUP(H8,'Customer Data'!A8,'Customer Data'!C8) -> Female | AI8: =_xlfn.XLOOKUP(H8,'Customer Data'!A8,'Customer Data'!D8) -> 33 | AJ8: =_xlfn.XLOOKUP(H8,'Customer Data'!A8,'Customer Data'!E8) -> Kano | AK8: =VLOOKUP(K8,'Product Category'!A:B,2,FALSE) -> Electronics | AL8: =VLOOKUP(Z8,Coupons!A:B,2,FALSE) -> 0.1 | AM8: =AE8*AL8 -> 66.442 | AN8: =N8*0.7 -> 465.094 | AO8: =AN8*L8 -> 465.094 | AP8: =AF8-AM8 -> 597.978 | AQ8: =AP8-AO8 -> 132.884 | AR8: =AP8/AO8 -> 1.2857143 | AS8: TOTAL DISCOUNT GIVEN | AT8: =SUM(AM2:AM1201) -> 75856.533
A9: ORD200007 | B9: =(RIGHT(A9, LEN(A9)-3))*1 -> 200007 | C9: 45058 | D9: 45058 | E9: =(TEXT(D9, "yyyy"))*1 -> 2023 | F9: =TEXT(D9, "mmmm") -> May | G9: =TEXT(D9, "dddd") -> Friday | H9: C41460 | I9: =(RIGHT(H9, LEN(H9)-1))*1 -> 41460 | J9: Monitor | K9: =TRIM(PROPER(J9)) -> Monitor | L9: 5 | M9: 149.55 | N9: =(TRIM(PROPER(M9)))*1 -> 149.55 | O9: 706 Main St | P9: =LEFT(O9, FIND(" ", O9)-1) -> 706 | Q9: =RIGHT(O9, LEN(O9) - FIND(" ", O9)) -> Main St | R9: Cash | S9: =TRIM(PROPER(R9)) -> Cash | T9: Shipped | U9: =TRIM(PROPER(T9)) -> Shipped | V9: TRK78809193 | W9: =RIGHT(V9, LEN(V9)-3) -> 78809193 | X9: 9 | Y9: FREESHIP | Z9: =TRIM(UPPER(IF(Y9="", "NO COUPON", Y9))) -> FREESHIP | AA9: =IF(Z9="NO COUPON","NO","YES") -> YES | AB9: Facebook | AC9: =TRIM(PROPER(AB9)) -> Facebook | AD9: 747.75 | AE9: 747.75 | AF9: =N9*L9 -> 747.75 | AG9: =_xlfn.XLOOKUP(H9, 'Customer Data'!A9,'Customer Data'!B9) -> Customer_9 | AH9: =_xlfn.XLOOKUP(H9,'Customer Data'!A9,'Customer Data'!C9) -> Female | AI9: =_xlfn.XLOOKUP(H9,'Customer Data'!A9,'Customer Data'!D9) -> 59 | AJ9: =_xlfn.XLOOKUP(H9,'Customer Data'!A9,'Customer Data'!E9) -> Owerri | AK9: =VLOOKUP(K9,'Product Category'!A:B,2,FALSE) -> Electronics | AL9: =VLOOKUP(Z9,Coupons!A:B,2,FALSE) -> 0 | AM9: =AE9*AL9 -> 0 | AN9: =N9*0.7 -> 104.685 | AO9: =AN9*L9 -> 523.425 | AP9: =AF9-AM9 -> 747.75 | AQ9: =AP9-AO9 -> 224.325 | AR9: =AP9/AO9 -> 1.4285714
A10: ORD200008 | B10: =(RIGHT(A10, LEN(A10)-3))*1 -> 200008 | C10: 45749 | D10: 45749 | E10: =(TEXT(D10, "yyyy"))*1 -> 2025 | F10: =TEXT(D10, "mmmm") -> April | G10: =TEXT(D10, "dddd") -> Wednesday | H10: C26817 | I10: =(RIGHT(H10, LEN(H10)-1))*1 -> 26817 | J10: Phone | K10: =TRIM(PROPER(J10)) -> Phone | L10: 2 | M10: 134.28 | N10: =(TRIM(PROPER(M10)))*1 -> 134.28 | O10: 904 Main St | P10: =LEFT(O10, FIND(" ", O10)-1) -> 904 | Q10: =RIGHT(O10, LEN(O10) - FIND(" ", O10)) -> Main St | R10: Gift Card | S10: =TRIM(PROPER(R10)) -> Gift Card | T10: Cancelled | U10: =TRIM(PROPER(T10)) -> Cancelled | V10: TRK61042692 | W10: =RIGHT(V10, LEN(V10)-3) -> 61042692 | X10: 2 | Z10: =TRIM(UPPER(IF(Y10="", "NO COUPON", Y10))) -> NO COUPON | AA10: =IF(Z10="NO COUPON","NO","YES") -> NO | AB10: Email | AC10: =TRIM(PROPER(AB10)) -> Email | AD10: 268.56 | AE10: 268.56 | AF10: =N10*L10 -> 268.56 | AG10: =_xlfn.XLOOKUP(H10, 'Customer Data'!A10,'Customer Data'!B10) -> Customer_10 | AH10: =_xlfn.XLOOKUP(H10,'Customer Data'!A10,'Customer Data'!C10) -> Male | AI10: =_xlfn.XLOOKUP(H10,'Customer Data'!A10,'Customer Data'!D10) -> 41 | AJ10: =_xlfn.XLOOKUP(H10,'Customer Data'!A10,'Customer Data'!E10) -> Port-Harcourt | AK10: =VLOOKUP(K10,'Product Category'!A:B,2,FALSE) -> Electronics | AL10: =VLOOKUP(Z10,Coupons!A:B,2,FALSE) -> 0 | AM10: =AE10*AL10 -> 0 | AN10: =N10*0.7 -> 93.996 | AO10: =AN10*L10 -> 187.992 | AP10: =AF10-AM10 -> 268.56 | AQ10: =AP10-AO10 -> 80.568 | AR10: =AP10/AO10 -> 1.4285714
A11: ORD200009 | B11: =(RIGHT(A11, LEN(A11)-3))*1 -> 200009 | C11: 45251 | D11: 45251 | E11: =(TEXT(D11, "yyyy"))*1 -> 2023 | F11: =TEXT(D11, "mmmm") -> November | G11: =TEXT(D11, "dddd") -> Tuesday | H11: C31946 | I11: =(RIGHT(H11, LEN(H11)-1))*1 -> 31946 | J11: Desk | K11: =TRIM(PROPER(J11)) -> Desk | L11: 4 | M11: 509.38 | N11: =(TRIM(PROPER(M11)))*1 -> 509.38 | O11: 102 Main St | P11: =LEFT(O11, FIND(" ", O11)-1) -> 102 | Q11: =RIGHT(O11, LEN(O11) - FIND(" ", O11)) -> Main St | R11: Credit Card | S11: =TRIM(PROPER(R11)) -> Credit Card | T11: Shipped | U11: =TRIM(PROPER(T11)) -> Shipped | V11: TRK33478363 | W11: =RIGHT(V11, LEN(V11)-3) -> 33478363 | X11: 6 | Y11: SAVE10 | Z11: =TRIM(UPPER(IF(Y11="", "NO COUPON", Y11))) -> SAVE10 | AA11: =IF(Z11="NO COUPON","NO","YES") -> YES | AB11: Google | AC11: =TRIM(PROPER(AB11)) -> Google | AD11: 2037.52 | AE11: 2037.52 | AF11: =N11*L11 -> 2037.52 | AG11: =_xlfn.XLOOKUP(H11, 'Customer Data'!A11,'Customer Data'!B11) -> Customer_11 | AH11: =_xlfn.XLOOKUP(H11,'Customer Data'!A11,'Customer Data'!C11) -> Female | AI11: =_xlfn.XLOOKUP(H11,'Customer Data'!A11,'Customer Data'!D11) -> 56 | AJ11: =_xlfn.XLOOKUP(H11,'Customer Data'!A11,'Customer Data'!E11) -> Kano | AK11: =VLOOKUP(K11,'Product Category'!A:B,2,FALSE) -> Furniture | AL11: =VLOOKUP(Z11,Coupons!A:B,2,FALSE) -> 0.1 | AM11: =AE11*AL11 -> 203.752 | AN11: =N11*0.7 -> 356.566 | AO11: =AN11*L11 -> 1426.264 | AP11: =AF11-AM11 -> 1833.768 | AQ11: =AP11-AO11 -> 407.504 | AR11: =AP11/AO11 -> 1.2857143
A12: ORD200010 | B12: =(RIGHT(A12, LEN(A12)-3))*1 -> 200010 | C12: 45289 | D12: 45289 | E12: =(TEXT(D12, "yyyy"))*1 -> 2023 | F12: =TEXT(D12, "mmmm") -> December | G12: =TEXT(D12, "dddd") -> Friday | H12: C43443 | I12: =(RIGHT(H12, LEN(H12)-1))*1 -> 43443 | J12: Tablet | K12: =TRIM(PROPER(J12)) -> Tablet | L12: 5 | M12: 625.97 | N12: =(TRIM(PROPER(M12)))*1 -> 625.97 | O12: 333 Main St | P12: =LEFT(O12, FIND(" ", O12)-1) -> 333 | Q12: =RIGHT(O12, LEN(O12) - FIND(" ", O12)) -> Main St | R12: Credit Card | S12: =TRIM(PROPER(R12)) -> Credit Card | T12: Returned | U12: =TRIM(PROPER(T12)) -> Returned | V12: TRK98859248 | W12: =RIGHT(V12, LEN(V12)-3) -> 98859248 | X12: 9 | Y12: WINTER15 | Z12: =TRIM(UPPER(IF(Y12="", "NO COUPON", Y12))) -> WINTER15 | AA12: =IF(Z12="NO COUPON","NO","YES") -> YES | AB12: Instagram | AC12: =TRIM(PROPER(AB12)) -> Instagram | AD12: 3129.85 | AE12: 3129.85 | AF12: =N12*L12 -> 3129.85 | AG12: =_xlfn.XLOOKUP(H12, 'Customer Data'!A12,'Customer Data'!B12) -> Customer_12 | AH12: =_xlfn.XLOOKUP(H12,'Customer Data'!A12,'Customer Data'!C12) -> Female | AI12: =_xlfn.XLOOKUP(H12,'Customer Data'!A12,'Customer Data'!D12) -> 21 | AJ12: =_xlfn.XLOOKUP(H12,'Customer Data'!A12,'Customer Data'!E12) -> Kano | AK12: =VLOOKUP(K12,'Product Category'!A:B,2,FALSE) -> Electronics | AL12: =VLOOKUP(Z12,Coupons!A:B,2,FALSE) -> 0.15 | AM12: =AE12*AL12 -> 469.4775 | AN12: =N12*0.7 -> 438.179 | AO12: =AN12*L12 -> 2190.895 | AP12: =AF12-AM12 -> 2660.3725 | AQ12: =AP12-AO12 -> 469.4775 | AR12: =AP12/AO12 -> 1.2142857
A13: ORD200011 | B13: =(RIGHT(A13, LEN(A13)-3))*1 -> 200011 | C13: 45339 | D13: 45339 | E13: =(TEXT(D13, "yyyy"))*1 -> 2024 | F13: =TEXT(D13, "mmmm") -> February | G13: =TEXT(D13, "dddd") -> Saturday | H13: C93861 | I13: =(RIGHT(H13, LEN(H13)-1))*1 -> 93861 | J13: Monitor | K13: =TRIM(PROPER(J13)) -> Monitor | L13: 3 | M13: 49.14 | N13: =(TRIM(PROPER(M13)))*1 -> 49.14 | O13: 831 Main St | P13: =LEFT(O13, FIND(" ", O13)-1) -> 831 | Q13: =RIGHT(O13, LEN(O13) - FIND(" ", O13)) -> Main St | R13: Online | S13: =TRIM(PROPER(R13)) -> Online | T13: Returned | U13: =TRIM(PROPER(T13)) -> Returned | V13: TRK48234646 | W13: =RIGHT(V13, LEN(V13)-3) -> 48234646 | X13: 7 | Y13: SAVE10 | Z13: =TRIM(UPPER(IF(Y13="", "NO COUPON", Y13))) -> SAVE10 | AA13: =IF(Z13="NO COUPON","NO","YES") -> YES | AB13: Email | AC13: =TRIM(PROPER(AB13)) -> Email | AD13: 147.42 | AE13: 147.42 | AF13: =N13*L13 -> 147.42 | AG13: =_xlfn.XLOOKUP(H13, 'Customer Data'!A13,'Customer Data'!B13) -> Customer_13 | AH13: =_xlfn.XLOOKUP(H13,'Customer Data'!A13,'Customer Data'!C13) -> Female | AI13: =_xlfn.XLOOKUP(H13,'Customer Data'!A13,'Customer Data'!D13) -> 19 | AJ13: =_xlfn.XLOOKUP(H13,'Customer Data'!A13,'Customer Data'!E13) -> Lagos | AK13: =VLOOKUP(K13,'Product Category'!A:B,2,FALSE) -> Electronics | AL13: =VLOOKUP(Z13,Coupons!A:B,2,FALSE) -> 0.1 | AM13: =AE13*AL13 -> 14.742 | AN13: =N13*0.7 -> 34.398 | AO13: =AN13*L13 -> 103.194 | AP13: =AF13-AM13 -> 132.678 | AQ13: =AP13-AO13 -> 29.484 | AR13: =AP13/AO13 -> 1.2857143
A14: ORD200012 | B14: =(RIGHT(A14, LEN(A14)-3))*1 -> 200012 | C14: 45580 | D14: 45580 | E14: =(TEXT(D14, "yyyy"))*1 -> 2024 | F14: =TEXT(D14, "mmmm") -> October | G14: =TEXT(D14, "dddd") -> Tuesday | H14: C38785 | I14: =(RIGHT(H14, LEN(H14)-1))*1 -> 38785 | J14: Monitor | K14: =TRIM(PROPER(J14)) -> Monitor | L14: 2 | M14: 180.5 | N14: =(TRIM(PROPER(M14)))*1 -> 180.5 | O14: 179 Main St | P14: =LEFT(O14, FIND(" ", O14)-1) -> 179 | Q14: =RIGHT(O14, LEN(O14) - FIND(" ", O14)) -> Main St | R14: Debit Card | S14: =TRIM(PROPER(R14)) -> Debit Card | T14: Pending | U14: =TRIM(PROPER(T14)) -> Pending | V14: TRK20419991 | W14: =RIGHT(V14, LEN(V14)-3) -> 20419991 | X14: 6 | Y14: FREESHIP | Z14: =TRIM(UPPER(IF(Y14="", "NO COUPON", Y14))) -> FREESHIP | AA14: =IF(Z14="NO COUPON","NO","YES") -> YES | AB14: Referral | AC14: =TRIM(PROPER(AB14)) -> Referral | AD14: 361 | AE14: 361 | AF14: =N14*L14 -> 361 | AG14: =_xlfn.XLOOKUP(H14, 'Customer Data'!A14,'Customer Data'!B14) -> Customer_14 | AH14: =_xlfn.XLOOKUP(H14,'Customer Data'!A14,'Customer Data'!C14) -> Female | AI14: =_xlfn.XLOOKUP(H14,'Customer Data'!A14,'Customer Data'!D14) -> 27 | AJ14: =_xlfn.XLOOKUP(H14,'Customer Data'!A14,'Customer Data'!E14) -> Enugu | AK14: =VLOOKUP(K14,'Product Category'!A:B,2,FALSE) -> Electronics | AL14: =VLOOKUP(Z14,Coupons!A:B,2,FALSE) -> 0 | AM14: =AE14*AL14 -> 0 | AN14: =N14*0.7 -> 126.35 | AO14: =AN14*L14 -> 252.7 | AP14: =AF14-AM14 -> 361 | AQ14: =AP14-AO14 -> 108.3 | AR14: =AP14/AO14 -> 1.4285714
A15: ORD200013 | B15: =(RIGHT(A15, LEN(A15)-3))*1 -> 200013 | C15: 45168 | D15: 45168 | E15: =(TEXT(D15, "yyyy"))*1 -> 2023 | F15: =TEXT(D15, "mmmm") -> August | G15: =TEXT(D15, "dddd") -> Wednesday | H15: C88348 | I15: =(RIGHT(H15, LEN(H15)-1))*1 -> 88348 | J15: Laptop | K15: =TRIM(PROPER(J15)) -> Laptop | L15: 3 | M15: 201.49 | N15: =(TRIM(PROPER(M15)))*1 -> 201.49 | O15: 903 Main St | P15: =LEFT(O15, FIND(" ", O15)-1) -> 903 | Q15: =RIGHT(O15, LEN(O15) - FIND(" ", O15)) -> Main St | R15: Credit Card | S15: =TRIM(PROPER(R15)) -> Credit Card | T15: Returned | U15: =TRIM(PROPER(T15)) -> Returned | V15: TRK81913874 | W15: =RIGHT(V15, LEN(V15)-3) -> 81913874 | X15: 4 | Y15: FREESHIP | Z15: =TRIM(UPPER(IF(Y15="", "NO COUPON", Y15))) -> FREESHIP | AA15: =IF(Z15="NO COUPON","NO","YES") -> YES | AB15: Facebook | AC15: =TRIM(PROPER(AB15)) -> Facebook | AD15: 604.47 | AE15: 604.47 | AF15: =N15*L15 -> 604.47 | AG15: =_xlfn.XLOOKUP(H15, 'Customer Data'!A15,'Customer Data'!B15) -> Customer_15 | AH15: =_xlfn.XLOOKUP(H15,'Customer Data'!A15,'Customer Data'!C15) -> Female | AI15: =_xlfn.XLOOKUP(H15,'Customer Data'!A15,'Customer Data'!D15) -> 40 | AJ15: =_xlfn.XLOOKUP(H15,'Customer Data'!A15,'Customer Data'!E15) -> Enugu | AK15: =VLOOKUP(K15,'Product Category'!A:B,2,FALSE) -> Electronics | AL15: =VLOOKUP(Z15,Coupons!A:B,2,FALSE) -> 0 | AM15: =AE15*AL15 -> 0 | AN15: =N15*0.7 -> 141.043 | AO15: =AN15*L15 -> 423.129 | AP15: =AF15-AM15 -> 604.47 | AQ15: =AP15-AO15 -> 181.341 | AR15: =AP15/AO15 -> 1.4285714
A16: ORD200014 | B16: =(RIGHT(A16, LEN(A16)-3))*1 -> 200014 | C16: 45012 | D16: 45012 | E16: =(TEXT(D16, "yyyy"))*1 -> 2023 | F16: =TEXT(D16, "mmmm") -> March | G16: =TEXT(D16, "dddd") -> Monday | H16: C98474 | I16: =(RIGHT(H16, LEN(H16)-1))*1 -> 98474 | J16: Tablet | K16: =TRIM(PROPER(J16)) -> Tablet | L16: 2 | M16: 393.33 | N16: =(TRIM(PROPER(M16)))*1 -> 393.33 | O16: 980 Main St | P16: =LEFT(O16, FIND(" ", O16)-1) -> 980 | Q16: =RIGHT(O16, LEN(O16) - FIND(" ", O16)) -> Main St | R16: Debit Card | S16: =TRIM(PROPER(R16)) -> Debit Card | T16: Pending | U16: =TRIM(PROPER(T16)) -> Pending | V16: TRK79186539 | W16: =RIGHT(V16, LEN(V16)-3) -> 79186539 | X16: 3 | Y16: SAVE10 | Z16: =TRIM(UPPER(IF(Y16="", "NO COUPON", Y16))) -> SAVE10 | AA16: =IF(Z16="NO COUPON","NO","YES") -> YES | AB16: Instagram | AC16: =TRIM(PROPER(AB16)) -> Instagram | AD16: 786.66 | AE16: 786.66 | AF16: =N16*L16 -> 786.66 | AG16: =_xlfn.XLOOKUP(H16, 'Customer Data'!A16,'Customer Data'!B16) -> Customer_16 | AH16: =_xlfn.XLOOKUP(H16,'Customer Data'!A16,'Customer Data'!C16) -> Male | AI16: =_xlfn.XLOOKUP(H16,'Customer Data'!A16,'Customer Data'!D16) -> 19 | AJ16: =_xlfn.XLOOKUP(H16,'Customer Data'!A16,'Customer Data'!E16) -> Owerri | AK16: =VLOOKUP(K16,'Product Category'!A:B,2,FALSE) -> Electronics | AL16: =VLOOKUP(Z16,Coupons!A:B,2,FALSE) -> 0.1 | AM16: =AE16*AL16 -> 78.666 | AN16: =N16*0.7 -> 275.331 | AO16: =AN16*L16 -> 550.662 | AP16: =AF16-AM16 -> 707.994 | AQ16: =AP16-AO16 -> 157.332 | AR16: =AP16/AO16 -> 1.2857143
A17: ORD200015 | B17: =(RIGHT(A17, LEN(A17)-3))*1 -> 200015 | C17: 45124 | D17: 45124 | E17: =(TEXT(D17, "yyyy"))*1 -> 2023 | F17: =TEXT(D17, "mmmm") -> July | G17: =TEXT(D17, "dddd") -> Monday | H17: C39416 | I17: =(RIGHT(H17, LEN(H17)-1))*1 -> 39416 | J17: Printer | K17: =TRIM(PROPER(J17)) -> Printer | L17: 1 | M17: 473.96 | N17: =(TRIM(PROPER(M17)))*1 -> 473.96 | O17: 942 Main St | P17: =LEFT(O17, FIND(" ", O17)-1) -> 942 | Q17: =RIGHT(O17, LEN(O17) - FIND(" ", O17)) -> Main St | R17: Cash | S17: =TRIM(PROPER(R17)) -> Cash | T17: Delivered | U17: =TRIM(PROPER(T17)) -> Delivered | V17: TRK54930938 | W17: =RIGHT(V17, LEN(V17)-3) -> 54930938 | X17: 3 | Z17: =TRIM(UPPER(IF(Y17="", "NO COUPON", Y17))) -> NO COUPON | AA17: =IF(Z17="NO COUPON","NO","YES") -> NO | AB17: Google | AC17: =TRIM(PROPER(AB17)) -> Google | AD17: 473.96 | AE17: 473.96 | AF17: =N17*L17 -> 473.96 | AG17: =_xlfn.XLOOKUP(H17, 'Customer Data'!A17,'Customer Data'!B17) -> Customer_17 | AH17: =_xlfn.XLOOKUP(H17,'Customer Data'!A17,'Customer Data'!C17) -> Female | AI17: =_xlfn.XLOOKUP(H17,'Customer Data'!A17,'Customer Data'!D17) -> 38 | AJ17: =_xlfn.XLOOKUP(H17,'Customer Data'!A17,'Customer Data'!E17) -> Kano | AK17: =VLOOKUP(K17,'Product Category'!A:B,2,FALSE) -> Electronics | AL17: =VLOOKUP(Z17,Coupons!A:B,2,FALSE) -> 0 | AM17: =AE17*AL17 -> 0 | AN17: =N17*0.7 -> 331.772 | AO17: =AN17*L17 -> 331.772 | AP17: =AF17-AM17 -> 473.96 | AQ17: =AP17-AO17 -> 142.188 | AR17: =AP17/AO17 -> 1.4285714
A18: ORD200016 | B18: =(RIGHT(A18, LEN(A18)-3))*1 -> 200016 | C18: 44950 | D18: 44950 | E18: =(TEXT(D18, "yyyy"))*1 -> 2023 | F18: =TEXT(D18, "mmmm") -> January | G18: =TEXT(D18, "dddd") -> Tuesday | H18: C28976 | I18: =(RIGHT(H18, LEN(H18)-1))*1 -> 28976 | J18: Printer | K18: =TRIM(PROPER(J18)) -> Printer | L18: 2 | M18: 533.81 | N18: =(TRIM(PROPER(M18)))*1 -> 533.81 | O18: 914 Main St | P18: =LEFT(O18, FIND(" ", O18)-1) -> 914 | Q18: =RIGHT(O18, LEN(O18) - FIND(" ", O18)) -> Main St | R18: Credit Card | S18: =TRIM(PROPER(R18)) -> Credit Card | T18: Pending | U18: =TRIM(PROPER(T18)) -> Pending | V18: TRK13194259 | W18: =RIGHT(V18, LEN(V18)-3) -> 13194259 | X18: 3 | Y18: FREESHIP | Z18: =TRIM(UPPER(IF(Y18="", "NO COUPON", Y18))) -> FREESHIP | AA18: =IF(Z18="NO COUPON","NO","YES") -> YES | AB18: Email | AC18: =TRIM(PROPER(AB18)) -> Email | AD18: 1067.62 | AE18: 1067.62 | AF18: =N18*L18 -> 1067.62 | AG18: =_xlfn.XLOOKUP(H18, 'Customer Data'!A18,'Customer Data'!B18) -> Customer_18 | AH18: =_xlfn.XLOOKUP(H18,'Customer Data'!A18,'Customer Data'!C18) -> Male | AI18: =_xlfn.XLOOKUP(H18,'Customer Data'!A18,'Customer Data'!D18) -> 51 | AJ18: =_xlfn.XLOOKUP(H18,'Customer Data'!A18,'Customer Data'!E18) -> Owerri | AK18: =VLOOKUP(K18,'Product Category'!A:B,2,FALSE) -> Electronics | AL18: =VLOOKUP(Z18,Coupons!A:B,2,FALSE) -> 0 | AM18: =AE18*AL18 -> 0 | AN18: =N18*0.7 -> 373.667 | AO18: =AN18*L18 -> 747.334 | AP18: =AF18-AM18 -> 1067.62 | AQ18: =AP18-AO18 -> 320.286 | AR18: =AP18/AO18 -> 1.4285714
A19: ORD200017 | B19: =(RIGHT(A19, LEN(A19)-3))*1 -> 200017 | C19: 45353 | D19: 45353 | E19: =(TEXT(D19, "yyyy"))*1 -> 2024 | F19: =TEXT(D19, "mmmm") -> March | G19: =TEXT(D19, "dddd") -> Saturday | H19: C60672 | I19: =(RIGHT(H19, LEN(H19)-1))*1 -> 60672 | J19: Tablet | K19: =TRIM(PROPER(J19)) -> Tablet | L19: 1 | M19: 423.4 | N19: =(TRIM(PROPER(M19)))*1 -> 423.4 | O19: 382 Main St | P19: =LEFT(O19, FIND(" ", O19)-1) -> 382 | Q19: =RIGHT(O19, LEN(O19) - FIND(" ", O19)) -> Main St | R19: Debit Card | S19: =TRIM(PROPER(R19)) -> Debit Card | T19: Shipped | U19: =TRIM(PROPER(T19)) -> Shipped | V19: TRK11972116 | W19: =RIGHT(V19, LEN(V19)-3) -> 11972116 | X19: 3 | Z19: =TRIM(UPPER(IF(Y19="", "NO COUPON", Y19))) -> NO COUPON | AA19: =IF(Z19="NO COUPON","NO","YES") -> NO | AB19: Referral | AC19: =TRIM(PROPER(AB19)) -> Referral | AD19: 423.4 | AE19: 423.4 | AF19: =N19*L19 -> 423.4 | AG19: =_xlfn.XLOOKUP(H19, 'Customer Data'!A19,'Customer Data'!B19) -> Customer_19 | AH19: =_xlfn.XLOOKUP(H19,'Customer Data'!A19,'Customer Data'!C19) -> Male | AI19: =_xlfn.XLOOKUP(H19,'Customer Data'!A19,'Customer Data'!D19) -> 37 | AJ19: =_xlfn.XLOOKUP(H19,'Customer Data'!A19,'Customer Data'!E19) -> Owerri | AK19: =VLOOKUP(K19,'Product Category'!A:B,2,FALSE) -> Electronics | AL19: =VLOOKUP(Z19,Coupons!A:B,2,FALSE) -> 0 | AM19: =AE19*AL19 -> 0 | AN19: =N19*0.7 -> 296.38 | AO19: =AN19*L19 -> 296.38 | AP19: =AF19-AM19 -> 423.4 | AQ19: =AP19-AO19 -> 127.02 | AR19: =AP19/AO19 -> 1.4285714
A20: ORD200018 | B20: =(RIGHT(A20, LEN(A20)-3))*1 -> 200018 | C20: 45742 | D20: 45742 | E20: =(TEXT(D20, "yyyy"))*1 -> 2025 | F20: =TEXT(D20, "mmmm") -> March | G20: =TEXT(D20, "dddd") -> Wednesday | H20: C84329 | I20: =(RIGHT(H20, LEN(H20)-1))*1 -> 84329 | J20: Desk | K20: =TRIM(PROPER(J20)) -> Desk | L20: 1 | M20: 431.44 | N20: =(TRIM(PROPER(M20)))*1 -> 431.44 | O20: 891 Main St | P20: =LEFT(O20, FIND(" ", O20)-1) -> 891 | Q20: =RIGHT(O20, LEN(O20) - FIND(" ", O20)) -> Main St | R20: Gift Card | S20: =TRIM(PROPER(R20)) -> Gift Card | T20: Pending | U20: =TRIM(PROPER(T20)) -> Pending | V20: TRK65191045 | W20: =RIGHT(V20, LEN(V20)-3) -> 65191045 | X20: 3 | Y20: SAVE10 | Z20: =TRIM(UPPER(IF(Y20="", "NO COUPON", Y20))) -> SAVE10 | AA20: =IF(Z20="NO COUPON","NO","YES") -> YES | AB20: Facebook | AC20: =TRIM(PROPER(AB20)) -> Facebook | AD20: 431.44 | AE20: 431.44 | AF20: =N20*L20 -> 431.44 | AG20: =_xlfn.XLOOKUP(H20, 'Customer Data'!A20,'Customer Data'!B20) -> Customer_20 | AH20: =_xlfn.XLOOKUP(H20,'Customer Data'!A20,'Customer Data'!C20) -> Female | AI20: =_xlfn.XLOOKUP(H20,'Customer Data'!A20,'Customer Data'!D20) -> 25 | AJ20: =_xlfn.XLOOKUP(H20,'Customer Data'!A20,'Customer Data'!E20) -> Owerri | AK20: =VLOOKUP(K20,'Product Category'!A:B,2,FALSE) -> Furniture | AL20: =VLOOKUP(Z20,Coupons!A:B,2,FALSE) -> 0.1 | AM20: =AE20*AL20 -> 43.144 | AN20: =N20*0.7 -> 302.008 | AO20: =AN20*L20 -> 302.008 | AP20: =AF20-AM20 -> 388.296 | AQ20: =AP20-AO20 -> 86.288 | AR20: =AP20/AO20 -> 1.2857143
A21: ORD200019 | B21: =(RIGHT(A21, LEN(A21)-3))*1 -> 200019 | C21: 44949 | D21: 44949 | E21: =(TEXT(D21, "yyyy"))*1 -> 2023 | F21: =TEXT(D21, "mmmm") -> January | G21: =TEXT(D21, "dddd") -> Monday | H21: C14552 | I21: =(RIGHT(H21, LEN(H21)-1))*1 -> 14552 | J21: Monitor | K21: =TRIM(PROPER(J21)) -> Monitor | L21: 5 | M21: 224 | N21: =(TRIM(PROPER(M21)))*1 -> 224 | O21: 273 Main St | P21: =LEFT(O21, FIND(" ", O21)-1) -> 273 | Q21: =RIGHT(O21, LEN(O21) - FIND(" ", O21)) -> Main St | R21: Cash | S21: =TRIM(PROPER(R21)) -> Cash | T21: Returned | U21: =TRIM(PROPER(T21)) -> Returned | V21: TRK59101365 | W21: =RIGHT(V21, LEN(V21)-3) -> 59101365 | X21: 9 | Y21: SAVE10 | Z21: =TRIM(UPPER(IF(Y21="", "NO COUPON", Y21))) -> SAVE10 | AA21: =IF(Z21="NO COUPON","NO","YES") -> YES | AB21: Google | AC21: =TRIM(PROPER(AB21)) -> Google | AD21: 1120 | AE21: 1120 | AF21: =N21*L21 -> 1120 | AG21: =_xlfn.XLOOKUP(H21, 'Customer Data'!A21,'Customer Data'!B21) -> Customer_21 | AH21: =_xlfn.XLOOKUP(H21,'Customer Data'!A21,'Customer Data'!C21) -> Female | AI21: =_xlfn.XLOOKUP(H21,'Customer Data'!A21,'Customer Data'!D21) -> 57 | AJ21: =_xlfn.XLOOKUP(H21,'Customer Data'!A21,'Customer Data'!E21) -> Abuja | AK21: =VLOOKUP(K21,'Product Category'!A:B,2,FALSE) -> Electronics | AL21: =VLOOKUP(Z21,Coupons!A:B,2,FALSE) -> 0.1 | AM21: =AE21*AL21 -> 112 | AN21: =N21*0.7 -> 156.8 | AO21: =AN21*L21 -> 784 | AP21: =AF21-AM21 -> 1008 | AQ21: =AP21-AO21 -> 224 | AR21: =AP21/AO21 -> 1.2857143
A22: ORD200020 | B22: =(RIGHT(A22, LEN(A22)-3))*1 -> 200020 | C22: 45054 | D22: 45054 | E22: =(TEXT(D22, "yyyy"))*1 -> 2023 | F22: =TEXT(D22, "mmmm") -> May | G22: =TEXT(D22, "dddd") -> Monday | H22: C54829 | I22: =(RIGHT(H22, LEN(H22)-1))*1 -> 54829 | J22: Chair | K22: =TRIM(PROPER(J22)) -> Chair | L22: 5 | M22: 62.51 | N22: =(TRIM(PROPER(M22)))*1 -> 62.51 | O22: 587 Main St | P22: =LEFT(O22, FIND(" ", O22)-1) -> 587 | Q22: =RIGHT(O22, LEN(O22) - FIND(" ", O22)) -> Main St | R22: Cash | S22: =TRIM(PROPER(R22)) -> Cash | T22: Pending | U22: =TRIM(PROPER(T22)) -> Pending | V22: TRK16718651 | W22: =RIGHT(V22, LEN(V22)-3) -> 16718651 | X22: 9 | Y22: WINTER15 | Z22: =TRIM(UPPER(IF(Y22="", "NO COUPON", Y22))) -> WINTER15 | AA22: =IF(Z22="NO COUPON","NO","YES") -> YES | AB22: Instagram | AC22: =TRIM(PROPER(AB22)) -> Instagram | AD22: 312.55 | AE22: 312.55 | AF22: =N22*L22 -> 312.55 | AG22: =_xlfn.XLOOKUP(H22, 'Customer Data'!A22,'Customer Data'!B22) -> Customer_22 | AH22: =_xlfn.XLOOKUP(H22,'Customer Data'!A22,'Customer Data'!C22) -> Female | AI22: =_xlfn.XLOOKUP(H22,'Customer Data'!A22,'Customer Data'!D22) -> 30 | AJ22: =_xlfn.XLOOKUP(H22,'Customer Data'!A22,'Customer Data'!E22) -> Owerri | AK22: =VLOOKUP(K22,'Product Category'!A:B,2,FALSE) -> Furniture | AL22: =VLOOKUP(Z22,Coupons!A:B,2,FALSE) -> 0.15 | AM22: =AE22*AL22 -> 46.8825 | AN22: =N22*0.7 -> 43.757 | AO22: =AN22*L22 -> 218.785 | AP22: =AF22-AM22 -> 265.6675 | AQ22: =AP22-AO22 -> 46.8825 | AR22: =AP22/AO22 -> 1.2142857
A23: ORD200021 | B23: =(RIGHT(A23, LEN(A23)-3))*1 -> 200021 | C23: 45613 | D23: 45613 | E23: =(TEXT(D23, "yyyy"))*1 -> 2024 | F23: =TEXT(D23, "mmmm") -> November | G23: =TEXT(D23, "dddd") -> Sunday | H23: C99023 | I23: =(RIGHT(H23, LEN(H23)-1))*1 -> 99023 | J23: Monitor | K23: =TRIM(PROPER(J23)) -> Monitor | L23: 4 | M23: 342.95 | N23: =(TRIM(PROPER(M23)))*1 -> 342.95 | O23: 569 Main St | P23: =LEFT(O23, FIND(" ", O23)-1) -> 569 | Q23: =RIGHT(O23, LEN(O23) - FIND(" ", O23)) -> Main St | R23: Cash | S23: =TRIM(PROPER(R23)) -> Cash | T23: Delivered | U23: =TRIM(PROPER(T23)) -> Delivered | V23: TRK52646983 | W23: =RIGHT(V23, LEN(V23)-3) -> 52646983 | X23: 6 | Z23: =TRIM(UPPER(IF(Y23="", "NO COUPON", Y23))) -> NO COUPON | AA23: =IF(Z23="NO COUPON","NO","YES") -> NO | AB23: Google | AC23: =TRIM(PROPER(AB23)) -> Google | AD23: 1371.8 | AE23: 1371.8 | AF23: =N23*L23 -> 1371.8 | AG23: =_xlfn.XLOOKUP(H23, 'Customer Data'!A23,'Customer Data'!B23) -> Customer_23 | AH23: =_xlfn.XLOOKUP(H23,'Customer Data'!A23,'Customer Data'!C23) -> Male | AI23: =_xlfn.XLOOKUP(H23,'Customer Data'!A23,'Customer Data'!D23) -> 57 | AJ23: =_xlfn.XLOOKUP(H23,'Customer Data'!A23,'Customer Data'!E23) -> Enugu | AK23: =VLOOKUP(K23,'Product Category'!A:B,2,FALSE) -> Electronics | AL23: =VLOOKUP(Z23,Coupons!A:B,2,FALSE) -> 0 | AM23: =AE23*AL23 -> 0 | AN23: =N23*0.7 -> 240.065 | AO23: =AN23*L23 -> 960.26 | AP23: =AF23-AM23 -> 1371.8 | AQ23: =AP23-AO23 -> 411.54 | AR23: =AP23/AO23 -> 1.4285714
A24: ORD200022 | B24: =(RIGHT(A24, LEN(A24)-3))*1 -> 200022 | C24: 44955 | D24: 44955 | E24: =(TEXT(D24, "yyyy"))*1 -> 2023 | F24: =TEXT(D24, "mmmm") -> January | G24: =TEXT(D24, "dddd") -> Sunday | H24: C34416 | I24: =(RIGHT(H24, LEN(H24)-1))*1 -> 34416 | J24: Monitor | K24: =TRIM(PROPER(J24)) -> Monitor | L24: 2 | M24: 49.62 | N24: =(TRIM(PROPER(M24)))*1 -> 49.62 | O24: 633 Main St | P24: =LEFT(O24, FIND(" ", O24)-1) -> 633 | Q24: =RIGHT(O24, LEN(O24) - FIND(" ", O24)) -> Main St | R24: Online | S24: =TRIM(PROPER(R24)) -> Online | T24: Pending | U24: =TRIM(PROPER(T24)) -> Pending | V24: TRK75937350 | W24: =RIGHT(V24, LEN(V24)-3) -> 75937350 | X24: 2 | Y24: SAVE10 | Z24: =TRIM(UPPER(IF(Y24="", "NO COUPON", Y24))) -> SAVE10 | AA24: =IF(Z24="NO COUPON","NO","YES") -> YES | AB24: Google | AC24: =TRIM(PROPER(AB24)) -> Google | AD24: 99.24 | AE24: 99.24 | AF24: =N24*L24 -> 99.24 | AG24: =_xlfn.XLOOKUP(H24, 'Customer Data'!A24,'Customer Data'!B24) -> Customer_24 | AH24: =_xlfn.XLOOKUP(H24,'Customer Data'!A24,'Customer Data'!C24) -> Male | AI24: =_xlfn.XLOOKUP(H24,'Customer Data'!A24,'Customer Data'!D24) -> 38 | AJ24: =_xlfn.XLOOKUP(H24,'Customer Data'!A24,'Customer Data'!E24) -> Enugu | AK24: =VLOOKUP(K24,'Product Category'!A:B,2,FALSE) -> Electronics | AL24: =VLOOKUP(Z24,Coupons!A:B,2,FALSE) -> 0.1 | AM24: =AE24*AL24 -> 9.924 | AN24: =N24*0.7 -> 34.734 | AO24: =AN24*L24 -> 69.468 | AP24: =AF24-AM24 -> 89.316 | AQ24: =AP24-AO24 -> 19.848 | AR24: =AP24/AO24 -> 1.2857143
A25: ORD200023 | B25: =(RIGHT(A25, LEN(A25)-3))*1 -> 200023 | C25: 45756 | D25: 45756 | E25: =(TEXT(D25, "yyyy"))*1 -> 2025 | F25: =TEXT(D25, "mmmm") -> April | G25: =TEXT(D25, "dddd") -> Wednesday | H25: C42372 | I25: =(RIGHT(H25, LEN(H25)-1))*1 -> 42372 | J25: Phone | K25: =TRIM(PROPER(J25)) -> Phone | L25: 4 | M25: 273.25 | N25: =(TRIM(PROPER(M25)))*1 -> 273.25 | O25: 755 Main St | P25: =LEFT(O25, FIND(" ", O25)-1) -> 755 | Q25: =RIGHT(O25, LEN(O25) - FIND(" ", O25)) -> Main St | R25: Debit Card | S25: =TRIM(PROPER(R25)) -> Debit Card | T25: Cancelled | U25: =TRIM(PROPER(T25)) -> Cancelled | V25: TRK36168083 | W25: =RIGHT(V25, LEN(V25)-3) -> 36168083 | X25: 5 | Y25: FREESHIP | Z25: =TRIM(UPPER(IF(Y25="", "NO COUPON", Y25))) -> FREESHIP | AA25: =IF(Z25="NO COUPON","NO","YES") -> YES | AB25: Referral | AC25: =TRIM(PROPER(AB25)) -> Referral | AD25: 1093 | AE25: 1093 | AF25: =N25*L25 -> 1093 | AG25: =_xlfn.XLOOKUP(H25, 'Customer Data'!A25,'Customer Data'!B25) -> Customer_25 | AH25: =_xlfn.XLOOKUP(H25,'Customer Data'!A25,'Customer Data'!C25) -> Male | AI25: =_xlfn.XLOOKUP(H25,'Customer Data'!A25,'Customer Data'!D25) -> 39 | AJ25: =_xlfn.XLOOKUP(H25,'Customer Data'!A25,'Customer Data'!E25) -> Abuja | AK25: =VLOOKUP(K25,'Product Category'!A:B,2,FALSE) -> Electronics | AL25: =VLOOKUP(Z25,Coupons!A:B,2,FALSE) -> 0 | AM25: =AE25*AL25 -> 0 | AN25: =N25*0.7 -> 191.275 | AO25: =AN25*L25 -> 765.1 | AP25: =AF25-AM25 -> 1093 | AQ25: =AP25-AO25 -> 327.9 | AR25: =AP25/AO25 -> 1.4285714
A26: ORD200024 | B26: =(RIGHT(A26, LEN(A26)-3))*1 -> 200024 | C26: 45595 | D26: 45595 | E26: =(TEXT(D26, "yyyy"))*1 -> 2024 | F26: =TEXT(D26, "mmmm") -> October | G26: =TEXT(D26, "dddd") -> Wednesday | H26: C17470 | I26: =(RIGHT(H26, LEN(H26)-1))*1 -> 17470 | J26: Laptop | K26: =TRIM(PROPER(J26)) -> Laptop | L26: 2 | M26: 230.95 | N26: =(TRIM(PROPER(M26)))*1 -> 230.95 | O26: 956 Main St | P26: =LEFT(O26, FIND(" ", O26)-1) -> 956 | Q26: =RIGHT(O26, LEN(O26) - FIND(" ", O26)) -> Main St | R26: Online | S26: =TRIM(PROPER(R26)) -> Online | T26: Delivered | U26: =TRIM(PROPER(T26)) -> Delivered | V26: TRK28775057 | W26: =RIGHT(V26, LEN(V26)-3) -> 28775057 | X26: 3 | Y26: WINTER15 | Z26: =TRIM(UPPER(IF(Y26="", "NO COUPON", Y26))) -> WINTER15 | AA26: =IF(Z26="NO COUPON","NO","YES") -> YES | AB26: Referral | AC26: =TRIM(PROPER(AB26)) -> Referral | AD26: 461.9 | AE26: 461.9 | AF26: =N26*L26 -> 461.9 | AG26: =_xlfn.XLOOKUP(H26, 'Customer Data'!A26,'Customer Data'!B26) -> Customer_26 | AH26: =_xlfn.XLOOKUP(H26,'Customer Data'!A26,'Customer Data'!C26) -> Male | AI26: =_xlfn.XLOOKUP(H26,'Customer Data'!A26,'Customer Data'!D26) -> 51 | AJ26: =_xlfn.XLOOKUP(H26,'Customer Data'!A26,'Customer Data'!E26) -> Kano | AK26: =VLOOKUP(K26,'Product Category'!A:B,2,FALSE) -> Electronics | AL26: =VLOOKUP(Z26,Coupons!A:B,2,FALSE) -> 0.15 | AM26: =AE26*AL26 -> 69.285 | AN26: =N26*0.7 -> 161.665 | AO26: =AN26*L26 -> 323.33 | AP26: =AF26-AM26 -> 392.615 | AQ26: =AP26-AO26 -> 69.285 | AR26: =AP26/AO26 -> 1.2142857
A27: ORD200025 | B27: =(RIGHT(A27, LEN(A27)-3))*1 -> 200025 | C27: 45497 | D27: 45497 | E27: =(TEXT(D27, "yyyy"))*1 -> 2024 | F27: =TEXT(D27, "mmmm") -> July | G27: =TEXT(D27, "dddd") -> Wednesday | H27: C42577 | I27: =(RIGHT(H27, LEN(H27)-1))*1 -> 42577 | J27: Monitor | K27: =TRIM(PROPER(J27)) -> Monitor | L27: 1 | M27: 399.98 | N27: =(TRIM(PROPER(M27)))*1 -> 399.98 | O27: 709 Main St | P27: =LEFT(O27, FIND(" ", O27)-1) -> 709 | Q27: =RIGHT(O27, LEN(O27) - FIND(" ", O27)) -> Main St | R27: Debit Card | S27: =TRIM(PROPER(R27)) -> Debit Card | T27: Delivered | U27: =TRIM(PROPER(T27)) -> Delivered | V27: TRK69423327 | W27: =RIGHT(V27, LEN(V27)-3) -> 69423327 | X27: 3 | Y27: WINTER15 | Z27: =TRIM(UPPER(IF(Y27="", "NO COUPON", Y27))) -> WINTER15 | AA27: =IF(Z27="NO COUPON","NO","YES") -> YES | AB27: Email | AC27: =TRIM(PROPER(AB27)) -> Email | AD27: 399.98 | AE27: 399.98 | AF27: =N27*L27 -> 399.98 | AG27: =_xlfn.XLOOKUP(H27, 'Customer Data'!A27,'Customer Data'!B27) -> Customer_27 | AH27: =_xlfn.XLOOKUP(H27,'Customer Data'!A27,'Customer Data'!C27) -> Female | AI27: =_xlfn.XLOOKUP(H27,'Customer Data'!A27,'Customer Data'!D27) -> 41 | AJ27: =_xlfn.XLOOKUP(H27,'Customer Data'!A27,'Customer Data'!E27) -> Port-Harcourt | AK27: =VLOOKUP(K27,'Product Category'!A:B,2,FALSE) -> Electronics | AL27: =VLOOKUP(Z27,Coupons!A:B,2,FALSE) -> 0.15 | AM27: =AE27*AL27 -> 59.997 | AN27: =N27*0.7 -> 279.986 | AO27: =AN27*L27 -> 279.986 | AP27: =AF27-AM27 -> 339.983 | AQ27: =AP27-AO27 -> 59.997 | AR27: =AP27/AO27 -> 1.2142857
A28: ORD200026 | B28: =(RIGHT(A28, LEN(A28)-3))*1 -> 200026 | C28: 45357 | D28: 45357 | E28: =(TEXT(D28, "yyyy"))*1 -> 2024 | F28: =TEXT(D28, "mmmm") -> March | G28: =TEXT(D28, "dddd") -> Wednesday | H28: C21944 | I28: =(RIGHT(H28, LEN(H28)-1))*1 -> 21944 | J28: Laptop | K28: =TRIM(PROPER(J28)) -> Laptop | L28: 5 | M28: 59.55 | N28: =(TRIM(PROPER(M28)))*1 -> 59.55 | O28: 296 Main St | P28: =LEFT(O28, FIND(" ", O28)-1) -> 296 | Q28: =RIGHT(O28, LEN(O28) - FIND(" ", O28)) -> Main St | R28: Online | S28: =TRIM(PROPER(R28)) -> Online | T28: Delivered | U28: =TRIM(PROPER(T28)) -> Delivered | V28: TRK80276812 | W28: =RIGHT(V28, LEN(V28)-3) -> 80276812 | X28: 6 | Z28: =TRIM(UPPER(IF(Y28="", "NO COUPON", Y28))) -> NO COUPON | AA28: =IF(Z28="NO COUPON","NO","YES") -> NO | AB28: Referral | AC28: =TRIM(PROPER(AB28)) -> Referral | AD28: 297.75 | AE28: 297.75 | AF28: =N28*L28 -> 297.75 | AG28: =_xlfn.XLOOKUP(H28, 'Customer Data'!A28,'Customer Data'!B28) -> Customer_28 | AH28: =_xlfn.XLOOKUP(H28,'Customer Data'!A28,'Customer Data'!C28) -> Female | AI28: =_xlfn.XLOOKUP(H28,'Customer Data'!A28,'Customer Data'!D28) -> 53 | AJ28: =_xlfn.XLOOKUP(H28,'Customer Data'!A28,'Customer Data'!E28) -> Abuja | AK28: =VLOOKUP(K28,'Product Category'!A:B,2,FALSE) -> Electronics | AL28: =VLOOKUP(Z28,Coupons!A:B,2,FALSE) -> 0 | AM28: =AE28*AL28 -> 0 | AN28: =N28*0.7 -> 41.685 | AO28: =AN28*L28 -> 208.425 | AP28: =AF28-AM28 -> 297.75 | AQ28: =AP28-AO28 -> 89.325 | AR28: =AP28/AO28 -> 1.4285714
A29: ORD200027 | B29: =(RIGHT(A29, LEN(A29)-3))*1 -> 200027 | C29: 45344 | D29: 45344 | E29: =(TEXT(D29, "yyyy"))*1 -> 2024 | F29: =TEXT(D29, "mmmm") -> February | G29: =TEXT(D29, "dddd") -> Thursday | H29: C97593 | I29: =(RIGHT(H29, LEN(H29)-1))*1 -> 97593 | J29: Printer | K29: =TRIM(PROPER(J29)) -> Printer | L29: 1 | M29: 472.74 | N29: =(TRIM(PROPER(M29)))*1 -> 472.74 | O29: 881 Main St | P29: =LEFT(O29, FIND(" ", O29)-1) -> 881 | Q29: =RIGHT(O29, LEN(O29) - FIND(" ", O29)) -> Main St | R29: Online | S29: =TRIM(PROPER(R29)) -> Online | T29: Shipped | U29: =TRIM(PROPER(T29)) -> Shipped | V29: TRK89117573 | W29: =RIGHT(V29, LEN(V29)-3) -> 89117573 | X29: 6 | Y29: WINTER15 | Z29: =TRIM(UPPER(IF(Y29="", "NO COUPON", Y29))) -> WINTER15 | AA29: =IF(Z29="NO COUPON","NO","YES") -> YES | AB29: Google | AC29: =TRIM(PROPER(AB29)) -> Google | AD29: 472.74 | AE29: 472.74 | AF29: =N29*L29 -> 472.74 | AG29: =_xlfn.XLOOKUP(H29, 'Customer Data'!A29,'Customer Data'!B29) -> Customer_29 | AH29: =_xlfn.XLOOKUP(H29,'Customer Data'!A29,'Customer Data'!C29) -> Female | AI29: =_xlfn.XLOOKUP(H29,'Customer Data'!A29,'Customer Data'!D29) -> 23 | AJ29: =_xlfn.XLOOKUP(H29,'Customer Data'!A29,'Customer Data'!E29) -> Port-Harcourt | AK29: =VLOOKUP(K29,'Product Category'!A:B,2,FALSE) -> Electronics | AL29: =VLOOKUP(Z29,Coupons!A:B,2,FALSE) -> 0.15 | AM29: =AE29*AL29 -> 70.911 | AN29: =N29*0.7 -> 330.918 | AO29: =AN29*L29 -> 330.918 | AP29: =AF29-AM29 -> 401.829 | AQ29: =AP29-AO29 -> 70.911 | AR29: =AP29/AO29 -> 1.2142857
A30: ORD200028 | B30: =(RIGHT(A30, LEN(A30)-3))*1 -> 200028 | C30: 45251 | D30: 45251 | E30: =(TEXT(D30, "yyyy"))*1 -> 2023 | F30: =TEXT(D30, "mmmm") -> November | G30: =TEXT(D30, "dddd") -> Tuesday | H30: C59823 | I30: =(RIGHT(H30, LEN(H30)-1))*1 -> 59823 | J30: Phone | K30: =TRIM(PROPER(J30)) -> Phone | L30: 4 | M30: 160.07 | N30: =(TRIM(PROPER(M30)))*1 -> 160.07 | O30: 568 Main St | P30: =LEFT(O30, FIND(" ", O30)-1) -> 568 | Q30: =RIGHT(O30, LEN(O30) - FIND(" ", O30)) -> Main St | R30: Online | S30: =TRIM(PROPER(R30)) -> Online | T30: Pending | U30: =TRIM(PROPER(T30)) -> Pending | V30: TRK65895539 | W30: =RIGHT(V30, LEN(V30)-3) -> 65895539 | X30: 5 | Z30: =TRIM(UPPER(IF(Y30="", "NO COUPON", Y30))) -> NO COUPON | AA30: =IF(Z30="NO COUPON","NO","YES") -> NO | AB30: Email | AC30: =TRIM(PROPER(AB30)) -> Email | AD30: 640.28 | AE30: 640.28 | AF30: =N30*L30 -> 640.28 | AG30: =_xlfn.XLOOKUP(H30, 'Customer Data'!A30,'Customer Data'!B30) -> Customer_30 | AH30: =_xlfn.XLOOKUP(H30,'Customer Data'!A30,'Customer Data'!C30) -> Female | AI30: =_xlfn.XLOOKUP(H30,'Customer Data'!A30,'Customer Data'!D30) -> 49 | AJ30: =_xlfn.XLOOKUP(H30,'Customer Data'!A30,'Customer Data'!E30) -> Abuja | AK30: =VLOOKUP(K30,'Product Category'!A:B,2,FALSE) -> Electronics | AL30: =VLOOKUP(Z30,Coupons!A:B,2,FALSE) -> 0 | AM30: =AE30*AL30 -> 0 | AN30: =N30*0.7 -> 112.049 | AO30: =AN30*L30 -> 448.196 | AP30: =AF30-AM30 -> 640.28 | AQ30: =AP30-AO30 -> 192.084 | AR30: =AP30/AO30 -> 1.4285714
A31: ORD200029 | B31: =(RIGHT(A31, LEN(A31)-3))*1 -> 200029 | C31: 45555 | D31: 45555 | E31: =(TEXT(D31, "yyyy"))*1 -> 2024 | F31: =TEXT(D31, "mmmm") -> September | G31: =TEXT(D31, "dddd") -> Friday | H31: C33260 | I31: =(RIGHT(H31, LEN(H31)-1))*1 -> 33260 | J31: Desk | K31: =TRIM(PROPER(J31)) -> Desk | L31: 3 | M31: 423.53 | N31: =(TRIM(PROPER(M31)))*1 -> 423.53 | O31: 930 Main St | P31: =LEFT(O31, FIND(" ", O31)-1) -> 930 | Q31: =RIGHT(O31, LEN(O31) - FIND(" ", O31)) -> Main St | R31: Credit Card | S31: =TRIM(PROPER(R31)) -> Credit Card | T31: Delivered | U31: =TRIM(PROPER(T31)) -> Delivered | V31: TRK59744090 | W31: =RIGHT(V31, LEN(V31)-3) -> 59744090 | X31: 6 | Y31: SAVE10 | Z31: =TRIM(UPPER(IF(Y31="", "NO COUPON", Y31))) -> SAVE10 | AA31: =IF(Z31="NO COUPON","NO","YES") -> YES | AB31: Referral | AC31: =TRIM(PROPER(AB31)) -> Referral | AD31: 1270.59 | AE31: 1270.59 | AF31: =N31*L31 -> 1270.59 | AG31: =_xlfn.XLOOKUP(H31, 'Customer Data'!A31,'Customer Data'!B31) -> Customer_31 | AH31: =_xlfn.XLOOKUP(H31,'Customer Data'!A31,'Customer Data'!C31) -> Male | AI31: =_xlfn.XLOOKUP(H31,'Customer Data'!A31,'Customer Data'!D31) -> 52 | AJ31: =_xlfn.XLOOKUP(H31,'Customer Data'!A31,'Customer Data'!E31) -> Lagos | AK31: =VLOOKUP(K31,'Product Category'!A:B,2,FALSE) -> Furniture | AL31: =VLOOKUP(Z31,Coupons!A:B,2,FALSE) -> 0.1 | AM31: =AE31*AL31 -> 127.059 | AN31: =N31*0.7 -> 296.471 | AO31: =AN31*L31 -> 889.413 | AP31: =AF31-AM31 -> 1143.531 | AQ31: =AP31-AO31 -> 254.118 | AR31: =AP31/AO31 -> 1.2857143
A32: ORD200030 | B32: =(RIGHT(A32, LEN(A32)-3))*1 -> 200030 | C32: 45738 | D32: 45738 | E32: =(TEXT(D32, "yyyy"))*1 -> 2025 | F32: =TEXT(D32, "mmmm") -> March | G32: =TEXT(D32, "dddd") -> Saturday | H32: C44267 | I32: =(RIGHT(H32, LEN(H32)-1))*1 -> 44267 | J32: Monitor | K32: =TRIM(PROPER(J32)) -> Monitor | L32: 2 | M32: 426.7 | N32: =(TRIM(PROPER(M32)))*1 -> 426.7 | O32: 895 Main St | P32: =LEFT(O32, FIND(" ", O32)-1) -> 895 | Q32: =RIGHT(O32, LEN(O32) - FIND(" ", O32)) -> Main St | R32: Online | S32: =TRIM(PROPER(R32)) -> Online | T32: Pending | U32: =TRIM(PROPER(T32)) -> Pending | V32: TRK54751444 | W32: =RIGHT(V32, LEN(V32)-3) -> 54751444 | X32: 5 | Y32: SAVE10 | Z32: =TRIM(UPPER(IF(Y32="", "NO COUPON", Y32))) -> SAVE10 | AA32: =IF(Z32="NO COUPON","NO","YES") -> YES | AB32: Referral | AC32: =TRIM(PROPER(AB32)) -> Referral | AD32: 853.4 | AE32: 853.4 | AF32: =N32*L32 -> 853.4 | AG32: =_xlfn.XLOOKUP(H32, 'Customer Data'!A32,'Customer Data'!B32) -> Customer_32 | AH32: =_xlfn.XLOOKUP(H32,'Customer Data'!A32,'Customer Data'!C32) -> Male | AI32: =_xlfn.XLOOKUP(H32,'Customer Data'!A32,'Customer Data'!D32) -> 52 | AJ32: =_xlfn.XLOOKUP(H32,'Customer Data'!A32,'Customer Data'!E32) -> Lagos | AK32: =VLOOKUP(K32,'Product Category'!A:B,2,FALSE) -> Electronics | AL32: =VLOOKUP(Z32,Coupons!A:B,2,FALSE) -> 0.1 | AM32: =AE32*AL32 -> 85.34 | AN32: =N32*0.7 -> 298.69 | AO32: =AN32*L32 -> 597.38 | AP32: =AF32-AM32 -> 768.06 | AQ32: =AP32-AO32 -> 170.68 | AR32: =AP32/AO32 -> 1.2857143
A33: ORD200031 | B33: =(RIGHT(A33, LEN(A33)-3))*1 -> 200031 | C33: 45107 | D33: 45107 | E33: =(TEXT(D33, "yyyy"))*1 -> 2023 | F33: =TEXT(D33, "mmmm") -> June | G33: =TEXT(D33, "dddd") -> Friday | H33: C26445 | I33: =(RIGHT(H33, LEN(H33)-1))*1 -> 26445 | J33: Chair | K33: =TRIM(PROPER(J33)) -> Chair | L33: 3 | M33: 500.08 | N33: =(TRIM(PROPER(M33)))*1 -> 500.08 | O33: 996 Main St | P33: =LEFT(O33, FIND(" ", O33)-1) -> 996 | Q33: =RIGHT(O33, LEN(O33) - FIND(" ", O33)) -> Main St | R33: Debit Card | S33: =TRIM(PROPER(R33)) -> Debit Card | T33: Returned | U33: =TRIM(PROPER(T33)) -> Returned | V33: TRK31229981 | W33: =RIGHT(V33, LEN(V33)-3) -> 31229981 | X33: 6 | Z33: =TRIM(UPPER(IF(Y33="", "NO COUPON", Y33))) -> NO COUPON | AA33: =IF(Z33="NO COUPON","NO","YES") -> NO | AB33: Facebook | AC33: =TRIM(PROPER(AB33)) -> Facebook | AD33: 1500.24 | AE33: 1500.24 | AF33: =N33*L33 -> 1500.24 | AG33: =_xlfn.XLOOKUP(H33, 'Customer Data'!A33,'Customer Data'!B33) -> Customer_33 | AH33: =_xlfn.XLOOKUP(H33,'Customer Data'!A33,'Customer Data'!C33) -> Female | AI33: =_xlfn.XLOOKUP(H33,'Customer Data'!A33,'Customer Data'!D33) -> 52 | AJ33: =_xlfn.XLOOKUP(H33,'Customer Data'!A33,'Customer Data'!E33) -> Port-Harcourt | AK33: =VLOOKUP(K33,'Product Category'!A:B,2,FALSE) -> Furniture | AL33: =VLOOKUP(Z33,Coupons!A:B,2,FALSE) -> 0 | AM33: =AE33*AL33 -> 0 | AN33: =N33*0.7 -> 350.056 | AO33: =AN33*L33 -> 1050.168 | AP33: =AF33-AM33 -> 1500.24 | AQ33: =AP33-AO33 -> 450.072 | AR33: =AP33/AO33 -> 1.4285714
A34: ORD200032 | B34: =(RIGHT(A34, LEN(A34)-3))*1 -> 200032 | C34: 45047 | D34: 45047 | E34: =(TEXT(D34, "yyyy"))*1 -> 2023 | F34: =TEXT(D34, "mmmm") -> May | G34: =TEXT(D34, "dddd") -> Monday | H34: C12388 | I34: =(RIGHT(H34, LEN(H34)-1))*1 -> 12388 | J34: Tablet | K34: =TRIM(PROPER(J34)) -> Tablet | L34: 5 | M34: 536.72 | N34: =(TRIM(PROPER(M34)))*1 -> 536.72 | O34: 830 Main St | P34: =LEFT(O34, FIND(" ", O34)-1) -> 830 | Q34: =RIGHT(O34, LEN(O34) - FIND(" ", O34)) -> Main St | R34: Cash | S34: =TRIM(PROPER(R34)) -> Cash | T34: Delivered | U34: =TRIM(PROPER(T34)) -> Delivered | V34: TRK99261395 | W34: =RIGHT(V34, LEN(V34)-3) -> 99261395 | X34: 10 | Z34: =TRIM(UPPER(IF(Y34="", "NO COUPON", Y34))) -> NO COUPON | AA34: =IF(Z34="NO COUPON","NO","YES") -> NO | AB34: Email | AC34: =TRIM(PROPER(AB34)) -> Email | AD34: 2683.6 | AE34: 2683.6 | AF34: =N34*L34 -> 2683.6 | AG34: =_xlfn.XLOOKUP(H34, 'Customer Data'!A34,'Customer Data'!B34) -> Customer_34 | AH34: =_xlfn.XLOOKUP(H34,'Customer Data'!A34,'Customer Data'!C34) -> Female | AI34: =_xlfn.XLOOKUP(H34,'Customer Data'!A34,'Customer Data'!D34) -> 26 | AJ34: =_xlfn.XLOOKUP(H34,'Customer Data'!A34,'Customer Data'!E34) -> Port-Harcourt | AK34: =VLOOKUP(K34,'Product Category'!A:B,2,FALSE) -> Electronics | AL34: =VLOOKUP(Z34,Coupons!A:B,2,FALSE) -> 0 | AM34: =AE34*AL34 -> 0 | AN34: =N34*0.7 -> 375.704 | AO34: =AN34*L34 -> 1878.52 | AP34: =AF34-AM34 -> 2683.6 | AQ34: =AP34-AO34 -> 805.08 | AR34: =AP34/AO34 -> 1.4285714
